Workbook

Sheet Start here
B2: Module 2 · Finding and Trusting Water Data — Practice workbook
B3: Water Data Literacy: Rainfall, Floods and Climate Change · Udemy edition · Dr Arpan Pradhan
B5: How to use this workbook
B6: This is the spreadsheet version of this module's practice activities. Same data, same questions and same answers as the Colab practice notebooks.
B7: 1. Go to File → Make a copy so you have your own version.
B8: 2. Type or choose your answers in the YELLOW cells with blue text. The CHECK column shows ✓ (correct) or ✗ (try again).
B9: 3. Green cells are calculated by formulas. Click one to see how it is worked out.
B11: Tabs
B12: S06 Datasets · S07 Three records · S08 Describe · S09 Messy record · S10 Data card
B13: Data tabs: Data (sample district daily), Three sources 2021 (illustrative), Messy record.
B14: All data here is illustrative or synthetic, for practice. Session 8 shows how to download real data for your own place.

Sheet S06 Datasets
B2: Session 6 · Which dataset first?
B4: # | C4: Question | D4: Your answer | E4: Check
B5: Q1 | C5: A newspaper wants to know whether your district's monsoon was deficient this year. | E5: =IF(OR(D5="",D5="choose"),"",IF(D5="IMD district rainfall","✓ Correct","✗ Try again"))
B6: Q2 | C6: A panchayat wants yesterday's rainfall for its own village. | E6: =IF(OR(D6="",D6="choose"),"",IF(D6="State telemetric network","✓ Correct","✗ Try again"))
B7: Q3 | C7: A school by the river wants to know if the river will cross the danger level tomorrow. | E7: =IF(OR(D7="",D7="choose"),"",IF(D7="CWC flood forecasts","✓ Correct","✗ Try again"))
B8: Q4 | C8: A farmer group wants to know whether the upstream reservoir is fuller than last year, this week. | E8: =IF(OR(D8="",D8="choose"),"",IF(D8="CWC reservoir bulletin","✓ Correct","✗ Try again"))
B9: Q5 | C9: A historian wants to compare rainfall in the 1918 drought with today. | E9: =IF(OR(D9="",D9="choose"),"",IF(D9="IMD gridded rainfall","✓ Correct","✗ Try again"))
B10: Q6 | C10: A researcher needs daily rainfall since 1981 for a hill village with no gauge, in minutes. | E10: =IF(OR(D10="",D10="choose"),"",IF(D10="NASA POWER","✓ Correct","✗ Try again"))
B11: Q7 | C11: A borewell owner wants to know if groundwater in the district has been falling. | E11: =IF(OR(D11="",D11="choose"),"",IF(D11="CGWB observation wells","✓ Correct","✗ Try again"))
B12: Q8 | C12: IMD's day ends at 8:30 am IST; a global dataset's day ends at midnight UTC. Which metadata item warns you? | E12: =IF(OR(D12="",D12="choose"),"",IF(D12="Day definition","✓ Correct","✗ Try again"))
C13: Score (out of 8) | E13: =COUNTIF(E5:E12,"✓*")

Sheet S07 Three records
B2: Session 7 · Stations, grids and satellites (illustrative 2021 data)
G4: Record | H4: Year total (mm) | I4: Wettest day (mm) | J4: Rainy days
G5: Rain gauge (point) | H5: =SUM('Three sources 2021'!B2:B366) | I5: =MAX('Three sources 2021'!B2:B366) | J5: =COUNTIF('Three sources 2021'!B2:B366,">=2.5")
G6: Gridded (area average) | H6: =SUM('Three sources 2021'!C2:C366) | I6: =MAX('Three sources 2021'!C2:C366) | J6: =COUNTIF('Three sources 2021'!C2:C366,">=2.5")
G7: Satellite estimate | H7: =SUM('Three sources 2021'!D2:D366) | I7: =MAX('Three sources 2021'!D2:D366) | J7: =COUNTIF('Three sources 2021'!D2:D366,">=2.5")
B9: # | C9: Question | D9: Your answer | E9: Check
B10: Q1 | C10: 2021 year total for the rain gauge (mm)? | E10: =IF(D10="","",IF(ABS(D10-(H5))<=MAX(ABS(H5)*0.02,0.01),"✓ Correct","✗ Try again"))
B11: Q2 | C11: % difference of satellite total from gauge total: (satellite − gauge) ÷ gauge × 100. | E11: =IF(D11="","",IF(ABS(D11-((H7-H5)/H5*100))<=MAX(ABS((H7-H5)/H5*100)*0.02,0.01),"✓ Correct","✗ Try again"))
B12: Q3 | C12: Which record has the highest wettest day? | E12: =IF(OR(D12="",D12="choose"),"",IF(D12=INDEX($G$5:$G$7,MATCH(MAX($I$5:$I$7),$I$5:$I$7,0)),"✓ Correct","✗ Try again"))
B13: Q4 | C13: How many mm lower is the gridded wettest day than the gauge wettest day? | E13: =IF(D13="","",IF(ABS(D13-(I5-I6))<=MAX(ABS(I5-I6)*0.02,0.01),"✓ Correct","✗ Try again"))
B14: Q5 | C14: Why does a grid usually show a smaller wettest day than one gauge? | E14: =IF(OR(D14="",D14="choose"),"",IF(D14="Grid values average a large area","✓ Correct","✗ Try again"))
B15: Q6 | C15: Best source for rain over the Bay of Bengal during a cyclone? | E15: =IF(OR(D15="",D15="choose"),"",IF(D15="Satellite estimate","✓ Correct","✗ Try again"))
C16: Score (out of 6) | E16: =COUNTIF(E10:E15,"✓*")

Sheet S08 Describe
B2: Session 8 · Describe the record (Data tab)
B4: # | C4: Question | D4: Your answer | E4: Check
B5: Q1 | C5: How many days are in the record? | E5: =IF(D5="","",IF(ABS(D5-(COUNT(Data!$A$2:$A$20000)))<=MAX(ABS(COUNT(Data!$A$2:$A$20000))*0,0.01),"✓ Correct","✗ Try again"))
B6: Q2 | C6: In which year does the record start? | E6: =IF(D6="","",IF(ABS(D6-(MIN(Data!$C$2:$C$20000)))<=MAX(ABS(MIN(Data!$C$2:$C$20000))*0,0.01),"✓ Correct","✗ Try again"))
B7: Q3 | C7: Average annual total over all years (mm)? (Use the Annual tab.) | E7: =IF(D7="","",IF(ABS(D7-(AVERAGE(Annual!B2:B45)))<=MAX(ABS(AVERAGE(Annual!B2:B45))*0.02,0.01),"✓ Correct","✗ Try again"))
B8: Q4 | C8: Which year had the highest annual total? | E8: =IF(D8="","",IF(ABS(D8-(INDEX(Annual!A2:A45,MATCH(MAX(Annual!B2:B45),Annual!B2:B45,0))))<=MAX(ABS(INDEX(Annual!A2:A45,MATCH(MAX(Annual!B2:B45),Annual!B2:B45,0)))*0,0.01),"✓ Correct","✗ Try again"))
B9: Q5 | C9: What % of days had exactly 0 mm? | E9: =IF(D9="","",IF(ABS(D9-(COUNTIF(Data!$B$2:$B$20000,0)/COUNT(Data!$B$2:$B$20000)*100))<=MAX(ABS(COUNTIF(Data!$B$2:$B$20000,0)/COUNT(Data!$B$2:$B$20000)*100)*0.02,0.01),"✓ Correct","✗ Try again"))
B10: Q6 | C10: Most important item on a data card for NASA POWER data? | E10: =IF(OR(D10="",D10="choose"),"",IF(D10="The source and its spatial detail","✓ Correct","✗ Try again"))
C11: Score (out of 6) | E11: =COUNTIF(E5:E10,"✓*")

Sheet S09 Messy record
B2: Session 9 · Investigate the Messy record tab
B4: # | C4: Question | D4: Your answer | E4: Check
B5: Q1 | C5: How many rows contain −999? | E5: =IF(D5="","",IF(ABS(D5-(COUNTIF('Messy record'!$B$2:$B$1088,-999)))<=MAX(ABS(COUNTIF('Messy record'!$B$2:$B$1088,-999))*0,0.01),"✓ Correct","✗ Try again"))
B6: Q2 | C6: How many blank cells in rain_mm? | E6: =IF(D6="","",IF(ABS(D6-(COUNTBLANK('Messy record'!$B$2:$B$1088)))<=MAX(ABS(COUNTBLANK('Messy record'!$B$2:$B$1088))*0,0.01),"✓ Correct","✗ Try again"))
B7: Q3 | C7: How many impossible values (below 0 or above 500, not counting −999)? | E7: =IF(D7="","",IF(ABS(D7-(COUNTIFS('Messy record'!$B$2:$B$1088,"<0",'Messy record'!$B$2:$B$1088,"<>-999")+COUNTIF('Messy record'!$B$2:$B$1088,">500")))<=MAX(ABS(COUNTIFS('Messy record'!$B$2:$B$1088,"<0",'Messy record'!$B$2:$B$1088,"<>-999")+COUNTIF('Messy record'!$B$2:$B$1088,">500"))*0,0.01),"✓ Correct","✗ Try again"))
B8: Q4 | C8: How many extra duplicate rows (dates appearing a second time)? | E8: =IF(D8="","",IF(ABS(D8-(COUNTIF('Messy record'!$D$2:$D$1088,FALSE)))<=MAX(ABS(COUNTIF('Messy record'!$D$2:$D$1088,FALSE))*0,0.01),"✓ Correct","✗ Try again"))
B9: Q5 | C9: How many days are missing entirely (no row at all)? Hint: last date − first date + 1 − number of distinct dates. | E9: =IF(D9="","",IF(ABS(D9-((DATEVALUE('Messy record'!A1088)-DATEVALUE('Messy record'!A2)+1)-COUNTIF('Messy record'!$D$2:$D$1088,TRUE)))<=MAX(ABS((DATEVALUE('Messy record'!A1088)-DATEVALUE('Messy record'!A2)+1)-COUNTIF('Messy record'!$D$2:$D$1088,TRUE))*0,0.01),"✓ Correct","✗ Try again"))
B10: Q6 | C10: Clean 2019 total: values from 0 to 500 only, first occurrence of each date only (mm)? | E10: =IF(D10="","",IF(ABS(D10-(SUMIFS('Messy record'!$B$2:$B$1088,'Messy record'!$C$2:$C$1088,2019,'Messy record'!$B$2:$B$1088,">=0",'Messy record'!$B$2:$B$1088,"<=500",'Messy record'!$D$2:$D$1088,TRUE)))<=MAX(ABS(SUMIFS('Messy record'!$B$2:$B$1088,'Messy record'!$C$2:$C$1088,2019,'Messy record'!$B$2:$B$1088,">=0",'Messy record'!$B$2:$B$1088,"<=500",'Messy record'!$D$2:$D$1088,TRUE))*0.02,0.01),"✓ Correct","✗ Try again"))
B11: Q7 | C11: 186.2 mm on one day, with heavy rain the days before. What should you do? | E11: =IF(OR(D11="",D11="choose"),"",IF(D11="Keep it after checking neighbours and another source","✓ Correct","✗ Try again"))
C12: Score (out of 7) | E12: =COUNTIF(E5:E11,"✓*")

Sheet S10 Data card
B2: Session 10 · Workshop: my district's data card (capstone step 2)
B3: Fill this in from the Session 10 notebook (or paste your district into the Data tab and use the Annual tab).
B5: Item | C5: My district
B6: District and state
B7: Source (dataset and parameter)
B8: Location used (lat, lon)
B9: Period
B10: Spatial detail
B11: Missing days / years below 95% complete
B12: 1991–2020 average (mm)
B13: IMD normal (mm) and difference (%)
B14: Wettest day (mm, date)
B15: Problems found
B16: My decision about using this data

Sheet Data
A1: Date | B1: Rain (mm) | C1: Year | D1: Month
A2: 29587 | B2: 0 | C2: =IF(A2="","",YEAR(A2)) | D2: =IF(A2="","",MONTH(A2)) | F2: Sample district (illustrative, synthetic), 1981–2024.
A3: 29588 | B3: 0 | C3: =IF(A3="","",YEAR(A3)) | D3: =IF(A3="","",MONTH(A3)) | F3: To use your own place: paste the date and rain_mm columns from the CSV you downloaded in Session 8 into columns A and B (starting at row 2, replacing these rows), and copy the Year and Month formulas down. Every table updates.
A4: 29589 | B4: 0 | C4: =IF(A4="","",YEAR(A4)) | D4: =IF(A4="","",MONTH(A4))
A5: 29590 | B5: 0 | C5: =IF(A5="","",YEAR(A5)) | D5: =IF(A5="","",MONTH(A5))
A6: 29591 | B6: 0 | C6: =IF(A6="","",YEAR(A6)) | D6: =IF(A6="","",MONTH(A6))
A7: 29592 | B7: 0 | C7: =IF(A7="","",YEAR(A7)) | D7: =IF(A7="","",MONTH(A7))
A8: 29593 | B8: 0 | C8: =IF(A8="","",YEAR(A8)) | D8: =IF(A8="","",MONTH(A8))
A9: 29594 | B9: 0 | C9: =IF(A9="","",YEAR(A9)) | D9: =IF(A9="","",MONTH(A9))
A10: 29595 | B10: 0 | C10: =IF(A10="","",YEAR(A10)) | D10: =IF(A10="","",MONTH(A10))
A11: 29596 | B11: 0 | C11: =IF(A11="","",YEAR(A11)) | D11: =IF(A11="","",MONTH(A11))
A12: 29597 | B12: 0 | C12: =IF(A12="","",YEAR(A12)) | D12: =IF(A12="","",MONTH(A12))
A13: 29598 | B13: 0 | C13: =IF(A13="","",YEAR(A13)) | D13: =IF(A13="","",MONTH(A13))
A14: 29599 | B14: 0 | C14: =IF(A14="","",YEAR(A14)) | D14: =IF(A14="","",MONTH(A14))
A15: 29600 | B15: 0 | C15: =IF(A15="","",YEAR(A15)) | D15: =IF(A15="","",MONTH(A15))
... A16072: 45657 | B16072: 0 | C16072: =IF(A16072="","",YEAR(A16072)) | D16072: =IF(A16072="","",MONTH(A16072))

Sheet Annual
A1: Year | B1: Total (mm) | C1: Jun–Sep (mm) | D1: Wettest day (mm) | E1: Rainy days | F1: Heavy days | G1: Rain per rainy day | H1: Jun–Sep departure (%)
A2: 1981 | B2: =SUMIFS(Data!$B$2:$B$20000,Data!$C$2:$C$20000,A2) | C2: =SUMIFS(Data!$B$2:$B$20000,Data!$C$2:$C$20000,A2,Data!$D$2:$D$20000,">=6",Data!$D$2:$D$20000,"<=9") | D2: =_xlfn.MAXIFS(Data!$B$2:$B$20000,Data!$C$2:$C$20000,A2) | E2: =COUNTIFS(Data!$C$2:$C$20000,A2,Data!$B$2:$B$20000,">=2.5") | F2: =COUNTIFS(Data!$C$2:$C$20000,A2,Data!$B$2:$B$20000,">=64.5") | G2: =B2/E2 | H2: =(C2-$K$3)/$K$3*100 | J2: Normal annual (1991–2020, mm) | K2: =AVERAGEIFS(B2:B45,A2:A45,">=1991",A2:A45,"<=2020")
A3: 1982 | B3: =SUMIFS(Data!$B$2:$B$20000,Data!$C$2:$C$20000,A3) | C3: =SUMIFS(Data!$B$2:$B$20000,Data!$C$2:$C$20000,A3,Data!$D$2:$D$20000,">=6",Data!$D$2:$D$20000,"<=9") | D3: =_xlfn.MAXIFS(Data!$B$2:$B$20000,Data!$C$2:$C$20000,A3) | E3: =COUNTIFS(Data!$C$2:$C$20000,A3,Data!$B$2:$B$20000,">=2.5") | F3: =COUNTIFS(Data!$C$2:$C$20000,A3,Data!$B$2:$B$20000,">=64.5") | G3: =B3/E3 | H3: =(C3-$K$3)/$K$3*100 | J3: Normal Jun–Sep (1991–2020, mm) | K3: =AVERAGEIFS(C2:C45,A2:A45,">=1991",A2:A45,"<=2020")
A4: 1983 | B4: =SUMIFS(Data!$B$2:$B$20000,Data!$C$2:$C$20000,A4) | C4: =SUMIFS(Data!$B$2:$B$20000,Data!$C$2:$C$20000,A4,Data!$D$2:$D$20000,">=6",Data!$D$2:$D$20000,"<=9") | D4: =_xlfn.MAXIFS(Data!$B$2:$B$20000,Data!$C$2:$C$20000,A4) | E4: =COUNTIFS(Data!$C$2:$C$20000,A4,Data!$B$2:$B$20000,">=2.5") | F4: =COUNTIFS(Data!$C$2:$C$20000,A4,Data!$B$2:$B$20000,">=64.5") | G4: =B4/E4 | H4: =(C4-$K$3)/$K$3*100
A5: 1984 | B5: =SUMIFS(Data!$B$2:$B$20000,Data!$C$2:$C$20000,A5) | C5: =SUMIFS(Data!$B$2:$B$20000,Data!$C$2:$C$20000,A5,Data!$D$2:$D$20000,">=6",Data!$D$2:$D$20000,"<=9") | D5: =_xlfn.MAXIFS(Data!$B$2:$B$20000,Data!$C$2:$C$20000,A5) | E5: =COUNTIFS(Data!$C$2:$C$20000,A5,Data!$B$2:$B$20000,">=2.5") | F5: =COUNTIFS(Data!$C$2:$C$20000,A5,Data!$B$2:$B$20000,">=64.5") | G5: =B5/E5 | H5: =(C5-$K$3)/$K$3*100
A6: 1985 | B6: =SUMIFS(Data!$B$2:$B$20000,Data!$C$2:$C$20000,A6) | C6: =SUMIFS(Data!$B$2:$B$20000,Data!$C$2:$C$20000,A6,Data!$D$2:$D$20000,">=6",Data!$D$2:$D$20000,"<=9") | D6: =_xlfn.MAXIFS(Data!$B$2:$B$20000,Data!$C$2:$C$20000,A6) | E6: =COUNTIFS(Data!$C$2:$C$20000,A6,Data!$B$2:$B$20000,">=2.5") | F6: =COUNTIFS(Data!$C$2:$C$20000,A6,Data!$B$2:$B$20000,">=64.5") | G6: =B6/E6 | H6: =(C6-$K$3)/$K$3*100
A7: 1986 | B7: =SUMIFS(Data!$B$2:$B$20000,Data!$C$2:$C$20000,A7) | C7: =SUMIFS(Data!$B$2:$B$20000,Data!$C$2:$C$20000,A7,Data!$D$2:$D$20000,">=6",Data!$D$2:$D$20000,"<=9") | D7: =_xlfn.MAXIFS(Data!$B$2:$B$20000,Data!$C$2:$C$20000,A7) | E7: =COUNTIFS(Data!$C$2:$C$20000,A7,Data!$B$2:$B$20000,">=2.5") | F7: =COUNTIFS(Data!$C$2:$C$20000,A7,Data!$B$2:$B$20000,">=64.5") | G7: =B7/E7 | H7: =(C7-$K$3)/$K$3*100
A8: 1987 | B8: =SUMIFS(Data!$B$2:$B$20000,Data!$C$2:$C$20000,A8) | C8: =SUMIFS(Data!$B$2:$B$20000,Data!$C$2:$C$20000,A8,Data!$D$2:$D$20000,">=6",Data!$D$2:$D$20000,"<=9") | D8: =_xlfn.MAXIFS(Data!$B$2:$B$20000,Data!$C$2:$C$20000,A8) | E8: =COUNTIFS(Data!$C$2:$C$20000,A8,Data!$B$2:$B$20000,">=2.5") | F8: =COUNTIFS(Data!$C$2:$C$20000,A8,Data!$B$2:$B$20000,">=64.5") | G8: =B8/E8 | H8: =(C8-$K$3)/$K$3*100
A9: 1988 | B9: =SUMIFS(Data!$B$2:$B$20000,Data!$C$2:$C$20000,A9) | C9: =SUMIFS(Data!$B$2:$B$20000,Data!$C$2:$C$20000,A9,Data!$D$2:$D$20000,">=6",Data!$D$2:$D$20000,"<=9") | D9: =_xlfn.MAXIFS(Data!$B$2:$B$20000,Data!$C$2:$C$20000,A9) | E9: =COUNTIFS(Data!$C$2:$C$20000,A9,Data!$B$2:$B$20000,">=2.5") | F9: =COUNTIFS(Data!$C$2:$C$20000,A9,Data!$B$2:$B$20000,">=64.5") | G9: =B9/E9 | H9: =(C9-$K$3)/$K$3*100
A10: 1989 | B10: =SUMIFS(Data!$B$2:$B$20000,Data!$C$2:$C$20000,A10) | C10: =SUMIFS(Data!$B$2:$B$20000,Data!$C$2:$C$20000,A10,Data!$D$2:$D$20000,">=6",Data!$D$2:$D$20000,"<=9") | D10: =_xlfn.MAXIFS(Data!$B$2:$B$20000,Data!$C$2:$C$20000,A10) | E10: =COUNTIFS(Data!$C$2:$C$20000,A10,Data!$B$2:$B$20000,">=2.5") | F10: =COUNTIFS(Data!$C$2:$C$20000,A10,Data!$B$2:$B$20000,">=64.5") | G10: =B10/E10 | H10: =(C10-$K$3)/$K$3*100
A11: 1990 | B11: =SUMIFS(Data!$B$2:$B$20000,Data!$C$2:$C$20000,A11) | C11: =SUMIFS(Data!$B$2:$B$20000,Data!$C$2:$C$20000,A11,Data!$D$2:$D$20000,">=6",Data!$D$2:$D$20000,"<=9") | D11: =_xlfn.MAXIFS(Data!$B$2:$B$20000,Data!$C$2:$C$20000,A11) | E11: =COUNTIFS(Data!$C$2:$C$20000,A11,Data!$B$2:$B$20000,">=2.5") | F11: =COUNTIFS(Data!$C$2:$C$20000,A11,Data!$B$2:$B$20000,">=64.5") | G11: =B11/E11 | H11: =(C11-$K$3)/$K$3*100
A12: 1991 | B12: =SUMIFS(Data!$B$2:$B$20000,Data!$C$2:$C$20000,A12) | C12: =SUMIFS(Data!$B$2:$B$20000,Data!$C$2:$C$20000,A12,Data!$D$2:$D$20000,">=6",Data!$D$2:$D$20000,"<=9") | D12: =_xlfn.MAXIFS(Data!$B$2:$B$20000,Data!$C$2:$C$20000,A12) | E12: =COUNTIFS(Data!$C$2:$C$20000,A12,Data!$B$2:$B$20000,">=2.5") | F12: =COUNTIFS(Data!$C$2:$C$20000,A12,Data!$B$2:$B$20000,">=64.5") | G12: =B12/E12 | H12: =(C12-$K$3)/$K$3*100
A13: 1992 | B13: =SUMIFS(Data!$B$2:$B$20000,Data!$C$2:$C$20000,A13) | C13: =SUMIFS(Data!$B$2:$B$20000,Data!$C$2:$C$20000,A13,Data!$D$2:$D$20000,">=6",Data!$D$2:$D$20000,"<=9") | D13: =_xlfn.MAXIFS(Data!$B$2:$B$20000,Data!$C$2:$C$20000,A13) | E13: =COUNTIFS(Data!$C$2:$C$20000,A13,Data!$B$2:$B$20000,">=2.5") | F13: =COUNTIFS(Data!$C$2:$C$20000,A13,Data!$B$2:$B$20000,">=64.5") | G13: =B13/E13 | H13: =(C13-$K$3)/$K$3*100
A14: 1993 | B14: =SUMIFS(Data!$B$2:$B$20000,Data!$C$2:$C$20000,A14) | C14: =SUMIFS(Data!$B$2:$B$20000,Data!$C$2:$C$20000,A14,Data!$D$2:$D$20000,">=6",Data!$D$2:$D$20000,"<=9") | D14: =_xlfn.MAXIFS(Data!$B$2:$B$20000,Data!$C$2:$C$20000,A14) | E14: =COUNTIFS(Data!$C$2:$C$20000,A14,Data!$B$2:$B$20000,">=2.5") | F14: =COUNTIFS(Data!$C$2:$C$20000,A14,Data!$B$2:$B$20000,">=64.5") | G14: =B14/E14 | H14: =(C14-$K$3)/$K$3*100
A15: 1994 | B15: =SUMIFS(Data!$B$2:$B$20000,Data!$C$2:$C$20000,A15) | C15: =SUMIFS(Data!$B$2:$B$20000,Data!$C$2:$C$20000,A15,Data!$D$2:$D$20000,">=6",Data!$D$2:$D$20000,"<=9") | D15: =_xlfn.MAXIFS(Data!$B$2:$B$20000,Data!$C$2:$C$20000,A15) | E15: =COUNTIFS(Data!$C$2:$C$20000,A15,Data!$B$2:$B$20000,">=2.5") | F15: =COUNTIFS(Data!$C$2:$C$20000,A15,Data!$B$2:$B$20000,">=64.5") | G15: =B15/E15 | H15: =(C15-$K$3)/$K$3*100
... A45: 2024 | B45: =SUMIFS(Data!$B$2:$B$20000,Data!$C$2:$C$20000,A45) | C45: =SUMIFS(Data!$B$2:$B$20000,Data!$C$2:$C$20000,A45,Data!$D$2:$D$20000,">=6",Data!$D$2:$D$20000,"<=9") | D45: =_xlfn.MAXIFS(Data!$B$2:$B$20000,Data!$C$2:$C$20000,A45) | E45: =COUNTIFS(Data!$C$2:$C$20000,A45,Data!$B$2:$B$20000,">=2.5") | F45: =COUNTIFS(Data!$C$2:$C$20000,A45,Data!$B$2:$B$20000,">=64.5") | G45: =B45/E45 | H45: =(C45-$K$3)/$K$3*100

Sheet Three sources 2021
A1: Date | B1: Rain gauge (point) | C1: Gridded (area average) | D1: Satellite estimate
A2: 44197 | B2: 0 | C2: 0 | D2: 0
A3: 44198 | B3: 0 | C3: 0 | D3: 0
A4: 44199 | B4: 0 | C4: 0 | D4: 0
A5: 44200 | B5: 0 | C5: 0 | D5: 0
A6: 44201 | B6: 0 | C6: 0 | D6: 0
A7: 44202 | B7: 0 | C7: 0 | D7: 0
A8: 44203 | B8: 0 | C8: 0 | D8: 0
A9: 44204 | B9: 0 | C9: 0 | D9: 0
A10: 44205 | B10: 0 | C10: 0 | D10: 0
A11: 44206 | B11: 0 | C11: 0 | D11: 0
A12: 44207 | B12: 0 | C12: 0 | D12: 0
A13: 44208 | B13: 0 | C13: 0 | D13: 0
... A366: 44561 | B366: 0 | C366: 0 | D366: 0

Sheet Messy record
A1: date | B1: rain_mm | C1: year | D1: first time?
A2: 2018-01-01 | B2: 0 | C2: =VALUE(LEFT(A2,4)) | D2: =COUNTIF($A$2:A2,A2)=1
A3: 2018-01-02 | B3: 0 | C3: =VALUE(LEFT(A3,4)) | D3: =COUNTIF($A$2:A3,A3)=1
A4: 2018-01-03 | B4: 0 | C4: =VALUE(LEFT(A4,4)) | D4: =COUNTIF($A$2:A4,A4)=1
A5: 2018-01-04 | B5: 0 | C5: =VALUE(LEFT(A5,4)) | D5: =COUNTIF($A$2:A5,A5)=1
A6: 2018-01-05 | B6: 0 | C6: =VALUE(LEFT(A6,4)) | D6: =COUNTIF($A$2:A6,A6)=1
A7: 2018-01-06 | B7: 0 | C7: =VALUE(LEFT(A7,4)) | D7: =COUNTIF($A$2:A7,A7)=1
A8: 2018-01-07 | B8: 0 | C8: =VALUE(LEFT(A8,4)) | D8: =COUNTIF($A$2:A8,A8)=1
A9: 2018-01-08 | B9: 0 | C9: =VALUE(LEFT(A9,4)) | D9: =COUNTIF($A$2:A9,A9)=1
A10: 2018-01-09 | B10: 0 | C10: =VALUE(LEFT(A10,4)) | D10: =COUNTIF($A$2:A10,A10)=1
A11: 2018-01-10 | B11: 0 | C11: =VALUE(LEFT(A11,4)) | D11: =COUNTIF($A$2:A11,A11)=1
A12: 2018-01-11 | B12: 0 | C12: =VALUE(LEFT(A12,4)) | D12: =COUNTIF($A$2:A12,A12)=1
A13: 2018-01-12 | B13: 0 | C13: =VALUE(LEFT(A13,4)) | D13: =COUNTIF($A$2:A13,A13)=1
... A203: 2018-07-20 | B203: 23.2 | C203: =VALUE(LEFT(A203,4)) | D203: =COUNTIF($A$2:A203,A203)=1
A204: 2018-07-21 | C204: =VALUE(LEFT(A204,4)) | D204: =COUNTIF($A$2:A204,A204)=1
A205: 2018-07-22 | B205: 0 | C205: =VALUE(LEFT(A205,4)) | D205: =COUNTIF($A$2:A205,A205)=1
A206: 2018-07-23 | B206: 8.5 | C206: =VALUE(LEFT(A206,4)) | D206: =COUNTIF($A$2:A206,A206)=1
A207: 2018-07-24 | B207: 0 | C207: =VALUE(LEFT(A207,4)) | D207: =COUNTIF($A$2:A207,A207)=1
A208: 2018-07-25 | B208: 0 | C208: =VALUE(LEFT(A208,4)) | D208: =COUNTIF($A$2:A208,A208)=1
A209: 2018-07-26 | B209: 0 | C209: =VALUE(LEFT(A209,4)) | D209: =COUNTIF($A$2:A209,A209)=1
A210: 2018-07-27 | B210: 11.8 | C210: =VALUE(LEFT(A210,4)) | D210: =COUNTIF($A$2:A210,A210)=1
A211: 2018-07-28 | B211: 0 | C211: =VALUE(LEFT(A211,4)) | D211: =COUNTIF($A$2:A211,A211)=1
A212: 2018-07-29 | B212: 0 | C212: =VALUE(LEFT(A212,4)) | D212: =COUNTIF($A$2:A212,A212)=1
A213: 2018-07-30 | B213: 0 | C213: =VALUE(LEFT(A213,4)) | D213: =COUNTIF($A$2:A213,A213)=1
A214: 2018-07-31 | B214: 0.1 | C214: =VALUE(LEFT(A214,4)) | D214: =COUNTIF($A$2:A214,A214)=1
A215: 2018-08-01 | B215: 0 | C215: =VALUE(LEFT(A215,4)) | D215: =COUNTIF($A$2:A215,A215)=1
A216: 2018-08-02 | B216: 12.8 | C216: =VALUE(LEFT(A216,4)) | D216: =COUNTIF($A$2:A216,A216)=1
... A434: 2019-03-08 | B434: 0 | C434: =VALUE(LEFT(A434,4)) | D434: =COUNTIF($A$2:A434,A434)=1
A435: 2019-03-09 | C435: =VALUE(LEFT(A435,4)) | D435: =COUNTIF($A$2:A435,A435)=1
A436: 2019-03-10 | B436: 0 | C436: =VALUE(LEFT(A436,4)) | D436: =COUNTIF($A$2:A436,A436)=1
A437: 2019-03-11 | B437: 0 | C437: =VALUE(LEFT(A437,4)) | D437: =COUNTIF($A$2:A437,A437)=1
A438: 2019-03-12 | B438: 0 | C438: =VALUE(LEFT(A438,4)) | D438: =COUNTIF($A$2:A438,A438)=1
A439: 2019-03-13 | B439: 0 | C439: =VALUE(LEFT(A439,4)) | D439: =COUNTIF($A$2:A439,A439)=1
A440: 2019-03-14 | B440: 0 | C440: =VALUE(LEFT(A440,4)) | D440: =COUNTIF($A$2:A440,A440)=1
A441: 2019-03-15 | B441: 0 | C441: =VALUE(LEFT(A441,4)) | D441: =COUNTIF($A$2:A441,A441)=1
A442: 2019-03-16 | B442: 0 | C442: =VALUE(LEFT(A442,4)) | D442: =COUNTIF($A$2:A442,A442)=1
A443: 2019-03-17 | B443: 0 | C443: =VALUE(LEFT(A443,4)) | D443: =COUNTIF($A$2:A443,A443)=1
A444: 2019-03-18 | B444: 0 | C444: =VALUE(LEFT(A444,4)) | D444: =COUNTIF($A$2:A444,A444)=1
A445: 2019-03-19 | B445: 0 | C445: =VALUE(LEFT(A445,4)) | D445: =COUNTIF($A$2:A445,A445)=1
A446: 2019-03-20 | B446: 0 | C446: =VALUE(LEFT(A446,4)) | D446: =COUNTIF($A$2:A446,A446)=1
...
